{"error":{},"level":"error","message":"AuthController: Error durante el login del usuario","timestamp":"2025-08-05 14:31:18"}
{"level":"error","message":"GLOBAL ERROR HANDLER: Error capturado: TypeInfo not known for \"AuthService\"","name":"Error","stack":"Error: TypeInfo not known for \"AuthService\"\n    at C:\\Users\\PC\\Documents\\gestor-tareas-backend\\node_modules\\tsyringe\\dist\\cjs\\dependency-container.js:298:27\n    at InternalDependencyContainer.construct (C:\\Users\\PC\\Documents\\gestor-tareas-backend\\node_modules\\tsyringe\\dist\\cjs\\dependency-container.js:303:11)\n    at InternalDependencyContainer.resolve (C:\\Users\\PC\\Documents\\gestor-tareas-backend\\node_modules\\tsyringe\\dist\\cjs\\dependency-container.js:117:33)\n    at C:\\Users\\PC\\Documents\\gestor-tareas-backend\\node_modules\\tsyringe\\dist\\cjs\\dependency-container.js:289:54\n    at delayedObject (C:\\Users\\PC\\Documents\\gestor-tareas-backend\\node_modules\\tsyringe\\dist\\cjs\\lazy-helpers.js:27:25)\n    at Object.handler.<computed> [as get] (C:\\Users\\PC\\Documents\\gestor-tareas-backend\\node_modules\\tsyringe\\dist\\cjs\\lazy-helpers.js:38:27)\n    at AuthController.<anonymous> (C:\\Users\\PC\\Documents\\gestor-tareas-backend\\src\\controllers\\auth\\auth.controller.ts:32:51)\n    at step (C:\\Users\\PC\\Documents\\gestor-tareas-backend\\src\\controllers\\auth\\auth.controller.ts:45:23)\n    at Object.next (C:\\Users\\PC\\Documents\\gestor-tareas-backend\\src\\controllers\\auth\\auth.controller.ts:26:53)\n    at C:\\Users\\PC\\Documents\\gestor-tareas-backend\\src\\controllers\\auth\\auth.controller.ts:20:71","timestamp":"2025-08-05 14:31:18"}
{"errorLabelSet":{},"level":"error","message":"Ha ocurrido un error en el service findUser: UserService:  ClientSession cannot be serialized to BSON.","stack":"MongoRuntimeError: ClientSession cannot be serialized to BSON.\n    at ClientSession.toBSON (C:\\Users\\PC\\Documents\\gestor-tareas-backend\\node_modules\\mongodb\\src\\sessions.ts:684:11)\n    at serializeInto (C:\\Users\\PC\\Documents\\gestor-tareas-backend\\node_modules\\bson\\src\\parser\\serializer.ts:844:23)\n    at serializeObject (C:\\Users\\PC\\Documents\\gestor-tareas-backend\\node_modules\\bson\\src\\parser\\serializer.ts:295:20)\n    at serializeInto (C:\\Users\\PC\\Documents\\gestor-tareas-backend\\node_modules\\bson\\src\\parser\\serializer.ts:887:19)\n    at Object.serialize (C:\\Users\\PC\\Documents\\gestor-tareas-backend\\node_modules\\bson\\src\\bson.ts:108:30)\n    at OpMsgRequest.serializeBson (C:\\Users\\PC\\Documents\\gestor-tareas-backend\\node_modules\\mongodb\\src\\cmap\\commands.ts:617:17)\n    at OpMsgRequest.makeSections (C:\\Users\\PC\\Documents\\gestor-tareas-backend\\node_modules\\mongodb\\src\\cmap\\commands.ts:577:33)\n    at OpMsgRequest.toBin (C:\\Users\\PC\\Documents\\gestor-tareas-backend\\node_modules\\mongodb\\src\\cmap\\commands.ts:559:25)\n    at Connection.writeCommand (C:\\Users\\PC\\Documents\\gestor-tareas-backend\\node_modules\\mongodb\\src\\cmap\\connection.ts:705:53)\n    at Connection.sendWire (C:\\Users\\PC\\Documents\\gestor-tareas-backend\\node_modules\\mongodb\\src\\cmap\\connection.ts:464:18)","timestamp":"2025-08-05 14:50:37"}
{"code":1100,"httpStatusCode":1100,"level":"error","message":"Ha ocurrido un error en el service findUser: UserService:  El usuario no existe","name":"UserNotFoundError","stack":"UserNotFoundError: El usuario no existe\n    at UserNotFoundError.AppError [as constructor] (C:\\Users\\PC\\Documents\\gestor-tareas-backend\\src\\core\\types\\errors.ts:10:14)\n    at new UserNotFoundError (C:\\Users\\PC\\Documents\\gestor-tareas-backend\\src\\core\\exceptions\\users\\user.exception.ts:6:14)\n    at Function.UserValidator.validateUserExists (C:\\Users\\PC\\Documents\\gestor-tareas-backend\\src\\core\\validators\\userValidator.ts:17:25)\n    at UserService.<anonymous> (C:\\Users\\PC\\Documents\\gestor-tareas-backend\\src\\services\\user\\User.service.ts:85:27)\n    at step (C:\\Users\\PC\\Documents\\gestor-tareas-backend\\src\\services\\user\\User.service.ts:45:23)\n    at Object.next (C:\\Users\\PC\\Documents\\gestor-tareas-backend\\src\\services\\user\\User.service.ts:26:53)\n    at fulfilled (C:\\Users\\PC\\Documents\\gestor-tareas-backend\\src\\services\\user\\User.service.ts:17:58)\n    at processTicksAndRejections (node:internal/process/task_queues:95:5)","timestamp":"2025-08-05 14:55:38"}
{"error":{"code":1100,"httpStatusCode":1100,"name":"UserNotFoundError"},"level":"error","message":"AuthController: Error durante el login del usuario","timestamp":"2025-08-05 14:55:38"}
{"level":"error","message":"GLOBAL ERROR HANDLER: Error capturado: El usuario no existe","name":"UserNotFoundError","stack":"UserNotFoundError: El usuario no existe\n    at UserNotFoundError.AppError [as constructor] (C:\\Users\\PC\\Documents\\gestor-tareas-backend\\src\\core\\types\\errors.ts:10:14)\n    at new UserNotFoundError (C:\\Users\\PC\\Documents\\gestor-tareas-backend\\src\\core\\exceptions\\users\\user.exception.ts:6:14)\n    at Function.UserValidator.validateUserExists (C:\\Users\\PC\\Documents\\gestor-tareas-backend\\src\\core\\validators\\userValidator.ts:17:25)\n    at UserService.<anonymous> (C:\\Users\\PC\\Documents\\gestor-tareas-backend\\src\\services\\user\\User.service.ts:85:27)\n    at step (C:\\Users\\PC\\Documents\\gestor-tareas-backend\\src\\services\\user\\User.service.ts:45:23)\n    at Object.next (C:\\Users\\PC\\Documents\\gestor-tareas-backend\\src\\services\\user\\User.service.ts:26:53)\n    at fulfilled (C:\\Users\\PC\\Documents\\gestor-tareas-backend\\src\\services\\user\\User.service.ts:17:58)\n    at processTicksAndRejections (node:internal/process/task_queues:95:5)","timestamp":"2025-08-05 14:55:38"}
{"code":1100,"httpStatusCode":404,"level":"error","message":"Ha ocurrido un error en el service findUser: UserService:  El usuario no existe","name":"UserNotFoundError","stack":"UserNotFoundError: El usuario no existe\n    at UserNotFoundError.AppError [as constructor] (C:\\Users\\PC\\Documents\\gestor-tareas-backend\\src\\core\\types\\errors.ts:10:14)\n    at new UserNotFoundError (C:\\Users\\PC\\Documents\\gestor-tareas-backend\\src\\core\\exceptions\\users\\user.exception.ts:6:14)\n    at Function.UserValidator.validateUserExists (C:\\Users\\PC\\Documents\\gestor-tareas-backend\\src\\core\\validators\\userValidator.ts:17:25)\n    at UserService.<anonymous> (C:\\Users\\PC\\Documents\\gestor-tareas-backend\\src\\services\\user\\User.service.ts:85:27)\n    at step (C:\\Users\\PC\\Documents\\gestor-tareas-backend\\src\\services\\user\\User.service.ts:45:23)\n    at Object.next (C:\\Users\\PC\\Documents\\gestor-tareas-backend\\src\\services\\user\\User.service.ts:26:53)\n    at fulfilled (C:\\Users\\PC\\Documents\\gestor-tareas-backend\\src\\services\\user\\User.service.ts:17:58)\n    at processTicksAndRejections (node:internal/process/task_queues:95:5)","timestamp":"2025-08-05 15:02:24"}
{"error":{"code":500,"httpStatusCode":500,"name":"UnexpectedError","originalError":{}},"level":"error","message":"AuthController: Error durante el login del usuario","timestamp":"2025-08-05 15:02:24"}
{"level":"error","message":"GLOBAL ERROR HANDLER: Error capturado: Ha ocurrido un error inesperado: Cannot read properties of undefined (reading 'password'). Intente nuevamente.","name":"UnexpectedError","stack":"UnexpectedError: Ha ocurrido un error inesperado: Cannot read properties of undefined (reading 'password'). Intente nuevamente.\n    at UnexpectedError.AppError [as constructor] (C:\\Users\\PC\\Documents\\gestor-tareas-backend\\src\\core\\types\\errors.ts:10:14)\n    at new UnexpectedError (C:\\Users\\PC\\Documents\\gestor-tareas-backend\\src\\core\\types\\errors.ts:43:14)\n    at handleError (C:\\Users\\PC\\Documents\\gestor-tareas-backend\\src\\core\\utils\\handleErrors.ts:18:16)\n    at AuthService.<anonymous> (C:\\Users\\PC\\Documents\\gestor-tareas-backend\\src\\services\\auth\\Auth.service.ts:36:30)\n    at step (C:\\Users\\PC\\Documents\\gestor-tareas-backend\\src\\services\\auth\\Auth.service.ts:45:23)\n    at Object.next (C:\\Users\\PC\\Documents\\gestor-tareas-backend\\src\\services\\auth\\Auth.service.ts:26:53)\n    at fulfilled (C:\\Users\\PC\\Documents\\gestor-tareas-backend\\src\\services\\auth\\Auth.service.ts:17:58)\n    at processTicksAndRejections (node:internal/process/task_queues:95:5)","timestamp":"2025-08-05 15:02:24"}
{"code":1100,"httpStatusCode":404,"level":"error","message":"Ha ocurrido un error en el service findUser: UserService:  El usuario no existe","name":"UserNotFoundError","stack":"UserNotFoundError: El usuario no existe\n    at UserNotFoundError.AppError [as constructor] (C:\\Users\\PC\\Documents\\gestor-tareas-backend\\src\\core\\types\\errors.ts:10:14)\n    at new UserNotFoundError (C:\\Users\\PC\\Documents\\gestor-tareas-backend\\src\\core\\exceptions\\users\\user.exception.ts:6:14)\n    at Function.UserValidator.validateUserExists (C:\\Users\\PC\\Documents\\gestor-tareas-backend\\src\\core\\validators\\userValidator.ts:17:25)\n    at UserService.<anonymous> (C:\\Users\\PC\\Documents\\gestor-tareas-backend\\src\\services\\user\\User.service.ts:85:27)\n    at step (C:\\Users\\PC\\Documents\\gestor-tareas-backend\\src\\services\\user\\User.service.ts:45:23)\n    at Object.next (C:\\Users\\PC\\Documents\\gestor-tareas-backend\\src\\services\\user\\User.service.ts:26:53)\n    at fulfilled (C:\\Users\\PC\\Documents\\gestor-tareas-backend\\src\\services\\user\\User.service.ts:17:58)\n    at processTicksAndRejections (node:internal/process/task_queues:95:5)","timestamp":"2025-08-05 15:05:03"}
{"error":{"code":500,"httpStatusCode":500,"name":"UnexpectedError","originalError":{}},"level":"error","message":"AuthController: Error durante el login del usuario","timestamp":"2025-08-05 15:05:03"}
{"level":"error","message":"GLOBAL ERROR HANDLER: Error capturado: Ha ocurrido un error inesperado: Cannot read properties of undefined (reading 'password'). Intente nuevamente.","name":"UnexpectedError","stack":"UnexpectedError: Ha ocurrido un error inesperado: Cannot read properties of undefined (reading 'password'). Intente nuevamente.\n    at UnexpectedError.AppError [as constructor] (C:\\Users\\PC\\Documents\\gestor-tareas-backend\\src\\core\\types\\errors.ts:10:14)\n    at new UnexpectedError (C:\\Users\\PC\\Documents\\gestor-tareas-backend\\src\\core\\types\\errors.ts:43:14)\n    at handleError (C:\\Users\\PC\\Documents\\gestor-tareas-backend\\src\\core\\utils\\handleErrors.ts:18:16)\n    at AuthService.<anonymous> (C:\\Users\\PC\\Documents\\gestor-tareas-backend\\src\\services\\auth\\Auth.service.ts:36:30)\n    at step (C:\\Users\\PC\\Documents\\gestor-tareas-backend\\src\\services\\auth\\Auth.service.ts:45:23)\n    at Object.next (C:\\Users\\PC\\Documents\\gestor-tareas-backend\\src\\services\\auth\\Auth.service.ts:26:53)\n    at fulfilled (C:\\Users\\PC\\Documents\\gestor-tareas-backend\\src\\services\\auth\\Auth.service.ts:17:58)\n    at processTicksAndRejections (node:internal/process/task_queues:95:5)","timestamp":"2025-08-05 15:05:03"}
{"code":1100,"httpStatusCode":404,"level":"error","message":"Ha ocurrido un error en el service findUser: UserService:  El usuario no existe","name":"UserNotFoundError","stack":"UserNotFoundError: El usuario no existe\n    at UserNotFoundError.AppError [as constructor] (C:\\Users\\PC\\Documents\\gestor-tareas-backend\\src\\core\\types\\errors.ts:10:14)\n    at new UserNotFoundError (C:\\Users\\PC\\Documents\\gestor-tareas-backend\\src\\core\\exceptions\\users\\user.exception.ts:6:14)\n    at Function.UserValidator.validateUserExists (C:\\Users\\PC\\Documents\\gestor-tareas-backend\\src\\core\\validators\\userValidator.ts:17:25)\n    at UserService.<anonymous> (C:\\Users\\PC\\Documents\\gestor-tareas-backend\\src\\services\\user\\User.service.ts:85:27)\n    at step (C:\\Users\\PC\\Documents\\gestor-tareas-backend\\src\\services\\user\\User.service.ts:45:23)\n    at Object.next (C:\\Users\\PC\\Documents\\gestor-tareas-backend\\src\\services\\user\\User.service.ts:26:53)\n    at fulfilled (C:\\Users\\PC\\Documents\\gestor-tareas-backend\\src\\services\\user\\User.service.ts:17:58)\n    at processTicksAndRejections (node:internal/process/task_queues:95:5)","timestamp":"2025-08-05 15:10:11"}
{"error":{"code":1100,"httpStatusCode":404,"name":"UserNotFoundError"},"level":"error","message":"AuthController: Error durante el login del usuario","timestamp":"2025-08-05 15:10:11"}
{"level":"error","message":"GLOBAL ERROR HANDLER: Error capturado: El usuario no existe","name":"UserNotFoundError","stack":"UserNotFoundError: El usuario no existe\n    at UserNotFoundError.AppError [as constructor] (C:\\Users\\PC\\Documents\\gestor-tareas-backend\\src\\core\\types\\errors.ts:10:14)\n    at new UserNotFoundError (C:\\Users\\PC\\Documents\\gestor-tareas-backend\\src\\core\\exceptions\\users\\user.exception.ts:6:14)\n    at Function.UserValidator.validateUserExists (C:\\Users\\PC\\Documents\\gestor-tareas-backend\\src\\core\\validators\\userValidator.ts:17:25)\n    at UserService.<anonymous> (C:\\Users\\PC\\Documents\\gestor-tareas-backend\\src\\services\\user\\User.service.ts:85:27)\n    at step (C:\\Users\\PC\\Documents\\gestor-tareas-backend\\src\\services\\user\\User.service.ts:45:23)\n    at Object.next (C:\\Users\\PC\\Documents\\gestor-tareas-backend\\src\\services\\user\\User.service.ts:26:53)\n    at fulfilled (C:\\Users\\PC\\Documents\\gestor-tareas-backend\\src\\services\\user\\User.service.ts:17:58)\n    at processTicksAndRejections (node:internal/process/task_queues:95:5)","timestamp":"2025-08-05 15:10:11"}
